Workbook

Sheet Explanation of Dardel variables
A1: First page "dardel experiment results" is raw data, all other pages are trying to make graphs.
A4: purple highlight = | B4: Unicorns, meaning runs where the exact is different than approximate
A6: Column meanings
A7: M | B7: number of rectangles in M
A8: N | B8: number of rectangles in N
A9: Seed | B9: tells the seed number generating the rectangles
A10: match | B10: tells the matching distance; if exact is different than critical point approximate, then tells both
A11: crit_pt_lines_counted | B11: number of lines through critical points
A12: time_crit_pts
A13: exact_lines_counted | B13: number of lines through pairs of points in set used to compute exact mathching distance for our computation
A14: time_bneck
A15: time_switch | B15: time to compute set of switch points
A16: time_match_dist
A17: total_exact_time | B17: time switch + time match
A18: prune | B18: designates if it is with our new pruning or not

Sheet dardel_experiment_results
A1: M | B1: N | C1: seed | D1: match | E1: crit_pt_lines_counted | F1: time_crit_pts | G1: exact_lines_counted | H1: time_bneck | I1: time_switch | J1: time_match_dist | K1: total_exact_time | L1: prune | N1: Note: time_bneck is subset. Should have time_switch + time_match_dist = total_exact
A2: 1 | B2: 1 | C2: 9 | D2: crit_point_dist: 2.313, grid_dist: 2.52, exact_dist: 2.52 | E2: 27 | F2: 0.007 | G2: 7888 | H2: 0.393 | I2: 0.394 | J2: 0.419 | K2: 0.813 | L2: ALL (including NEW) PRUNING
A3: 1 | B3: 1 | C3: 11 | D3: crit_point_dist: 1.743, grid_dist: 1.853, exact_dist: 3.191 | E3: 18 | F3: 0.001 | G3: 6529 | H3: 0.391 | I3: 0.355 | J3: 0.414 | K3: 0.769 | L3: ALL (including NEW) PRUNING
A4: 1 | B4: 2 | C4: 9 | D4: crit_point_dist: 3.595, grid_dist: 3.308, exact_dist: 3.595 | E4: 119 | F4: 0.008 | G4: 174394 | H4: 10.917 | I4: 1.596 | J4: 11.781 | K4: 13.377 | L4: ALL (including NEW) PRUNING
A5: 1 | B5: 2 | C5: 10 | D5: crit_point_dist: 1.267, grid_dist: 1.299, exact_dist: 1.299 | E5: 131 | F5: 0.005 | G5: 326908 | H5: 11.478 | I5: 2.744 | J5: 13.112 | K5: 15.856 | L5: ALL (including NEW) PRUNING
A6: 1 | B6: 2 | C6: 11 | D6: crit_point_dist: 2.656, grid_dist: 2.656, exact_dist: 3.191 | E6: 101 | F6: 0.009 | G6: 191677 | H6: 14.562 | I6: 1.624 | J6: 15.596 | K6: 17.22 | L6: ALL (including NEW) PRUNING
A7: 1 | B7: 3 | C7: 4 | D7: crit_point_dist: 3.647, grid_dist: 1.708, exact_dist: 3.647 | E7: 314 | F7: 0.031 | G7: 2972808 | H7: 274.167 | I7: 9.499 | J7: 288.654 | K7: 298.154 | L7: ALL (including NEW) PRUNING
A8: 1 | B8: 3 | C8: 9 | D8: crit_point_dist: 3.595, grid_dist: 3.308, exact_dist: 3.595 | E8: 379 | F8: 0.027 | G8: 2355503 | H8: 161.112 | I8: 6.117 | J8: 171.765 | K8: 177.882 | L8: ALL (including NEW) PRUNING
A9: 1 | B9: 3 | C9: 10 | D9: crit_point_dist: 2.121, grid_dist: 2.1, exact_dist: 2.121 | E9: 358 | F9: 0.013 | G9: 3874986 | H9: 128.253 | I9: 9.768 | J9: 146.116 | K9: 155.884 | L9: ALL (including NEW) PRUNING
A10: 1 | B10: 3 | C10: 11 | D10: crit_point_dist: 2.656, grid_dist: 2.656, exact_dist: 3.191 | E10: 290 | F10: 0.023 | G10: 2268949 | H10: 153.459 | I10: 6.304 | J10: 164.85 | K10: 171.154 | L10: ALL (including NEW) PRUNING
A11: 1 | B11: 4 | C11: 4 | D11: crit_point_dist: 3.647, grid_dist: 1.708, exact_dist: 3.647 | E11: 678 | F11: 0.051 | G11: 17396810 | H11: 1373.328 | I11: 25.017 | J11: 1461.461 | K11: 1486.478 | L11: ALL (including NEW) PRUNING
A12: 1 | B12: 4 | C12: 9 | D12: crit_point_dist: 3.595, grid_dist: 3.308, exact_dist: 3.595 | E12: 761 | F12: 0.051 | G12: 11152198 | H12: 692.27 | I12: 14.754 | J12: 748.899 | K12: 763.654 | L12: ALL (including NEW) PRUNING
A13: 1 | B13: 4 | C13: 10 | D13: crit_point_dist: 2.121, grid_dist: 2.1, exact_dist: 2.121 | E13: 814 | F13: 0.035 | G13: 19787552 | H13: 730.555 | I13: 22.162 | J13: 819.801 | K13: 841.963 | L13: ALL (including NEW) PRUNING
... A251: 1 | B251: 5 | C251: 4 | D251: crit_point_dist: 3.647, grid_dist: 2.451, exact_dist: 3.647 | E251: 1380 | F251: 0.127 | G251: 777993469 | H251: 49735.033 | I251: 90.188 | J251: 54041.877 | K251: 54132.065 | L251: NO PRUNING WHATSOEVER
A252: 1 | B252: 1 | C252: 1 | D252: yes | E252: 16 | F252: 0.005 | G252: 48721 | H252: 0.546 | I252: 0.723 | J252: 0.772 | K252: 1.495 | L252: NO PRUNING WHATSOEVER | N252: time_bneck is subset of time_match_dist
A253: 1 | B253: 1 | C253: 2 | D253: yes | E253: 20 | F253: 0.027 | G253: 45932 | H253: 0.645 | I253: 0.703 | J253: 0.852 | K253: 1.555 | L253: NO PRUNING WHATSOEVER
A254: 1 | B254: 1 | C254: 3 | D254: yes | E254: 27 | F254: 0.081 | G254: 61515 | H254: 1.534 | I254: 0.847 | J254: 1.835 | K254: 2.682 | L254: NO PRUNING WHATSOEVER
A255: 1 | B255: 1 | C255: 4 | D255: yes | E255: 21 | F255: 0.084 | G255: 55326 | H255: 1.622 | I255: 0.882 | J255: 1.867 | K255: 2.749 | L255: NO PRUNING WHATSOEVER
A256: 1 | B256: 1 | C256: 5 | D256: yes | E256: 18 | F256: 0.082 | G256: 34310 | H256: 0.341 | I256: 1.009 | J256: 0.511 | K256: 1.52 | L256: NO PRUNING WHATSOEVER
A257: 1 | B257: 1 | C257: 6 | D257: yes | E257: 15 | F257: 0.029 | G257: 63525 | H257: 0.637 | I257: 0.738 | J257: 0.948 | K257: 1.686 | L257: NO PRUNING WHATSOEVER
A258: 1 | B258: 1 | C258: 7 | D258: yes | E258: 16 | F258: 0.03 | G258: 49323 | H258: 0.588 | I258: 0.75 | J258: 0.813 | K258: 1.563 | L258: NO PRUNING WHATSOEVER
A259: 1 | B259: 1 | C259: 8 | D259: yes | E259: 24 | F259: 0.016 | G259: 55880 | H259: 1.612 | I259: 0.599 | J259: 1.855 | K259: 2.454 | L259: NO PRUNING WHATSOEVER
A260: 1 | B260: 1 | C260: 10 | D260: yes | E260: 21 | F260: 0.005 | G260: 56334 | H260: 0.812 | I260: 0.582 | J260: 1.06 | K260: 1.642 | L260: NO PRUNING WHATSOEVER
A261: 1 | B261: 1 | C261: 12 | D261: yes | E261: 19 | F261: 0.005 | G261: 61263 | H261: 0.652 | I261: 0.624 | J261: 0.959 | K261: 1.583 | L261: NO PRUNING WHATSOEVER
A262: 1 | B262: 1 | C262: 13 | D262: yes | E262: 15 | F262: 0.017 | G262: 55798 | H262: 0.612 | I262: 0.643 | J262: 0.865 | K262: 1.508 | L262: NO PRUNING WHATSOEVER
A263: 1 | B263: 1 | C263: 14 | D263: yes | E263: 15 | F263: 0.016 | G263: 56702 | H263: 0.674 | I263: 0.595 | J263: 0.934 | K263: 1.53 | L263: NO PRUNING WHATSOEVER
A264: 1 | B264: 1 | C264: 15 | D264: yes | E264: 15 | F264: 0.02 | G264: 64258 | H264: 0.554 | I264: 0.619 | J264: 0.857 | K264: 1.476 | L264: NO PRUNING WHATSOEVER
... A703: 5 | B703: 1 | C703: 7 | D703: yes | E703: 1407 | F703: 0.174 | G703: 117216591 | H703: 9574.271 | I703: 69.532 | J703: 10101.416 | K703: 10170.95 | L703: ONLY OLD PRUNING

Sheet ratio all lines vs critical lin
A1: M | B1: N | C1: seed | D1: match | E1: crit_pt_lines_counted | F1: time_crit_pts | G1: exact_lines_counted | H1: ratio all over critical lines | I1: time_bneck | J1: time_switch | K1: time_match_dist | L1: total_exact_time | M1: prune | O1: Note: time_bneck is subset. Should have time_switch + time_match_dist = total_exact
A2: 1 | B2: 1 | C2: 1 | D2: yes | E2: 16 | F2: 0 | G2: 2854 | H2: =G2/E2 -> 178.375 | I2: 0.035 | J2: 0.338 | K2: 0.043 | L2: 0.382 | M2: ALL (including NEW) PRUNING | P2: M+N | Q2: Average ratio all lines/crit lines | R2: Standard deviation | S2: avg - st dev | T2: average + st dev
A3: 1 | B3: 1 | C3: 2 | D3: yes | E3: 20 | F3: 0 | G3: 5519 | H3: =G3/E3 -> 275.95 | I3: 0.088 | J3: 0.412 | K3: 0.118 | L3: 0.53 | M3: ALL (including NEW) PRUNING | P3: 2 | Q3: =AVERAGE(H2:H21) -> 235.08661 | R3: =STDEV(H2:H21) -> 59.800316 | S3: =Q3-R3 -> 175.28629 | T3: =Q3+R3 -> 294.88692
A4: 1 | B4: 1 | C4: 3 | D4: yes | E4: 27 | F4: 0.001 | G4: 6563 | H4: =G4/E4 -> 243.07407 | I4: 0.185 | J4: 0.364 | K4: 0.207 | L4: 0.57 | M4: ALL (including NEW) PRUNING | P4: 3 | Q4: =AVERAGE(H22:H61) -> 1626.3766 | R4: =STDEV(H22:H61) -> 529.23789 | S4: =Q4-R4 -> 1097.1388 | T4: =Q4+R4 -> 2155.6145
A5: 1 | B5: 1 | C5: 4 | D5: yes | E5: 21 | F5: 0.001 | G5: 6688 | H5: =G5/E5 -> 318.47619 | I5: 0.203 | J5: 0.391 | K5: 0.226 | L5: 0.617 | M5: ALL (including NEW) PRUNING | P5: 4 | Q5: =AVERAGE(H62:H121) -> 6274.3469 | R5: =STDEV(H62:H121) -> 2152.139 | S5: =Q5-R5 -> 4122.2079 | T5: =Q5+R5 -> 8426.486
A6: 1 | B6: 1 | C6: 5 | D6: yes | E6: 18 | F6: 0 | G6: 2144 | H6: =G6/E6 -> 119.11111 | I6: 0.026 | J6: 0.507 | K6: 0.031 | L6: 0.538 | M6: ALL (including NEW) PRUNING | P6: 5 | Q6: =AVERAGE(H122:H201) -> 16260.305 | R6: =STDEV(H122:H201) -> 6865.012 | S6: =Q6-R6 -> 9395.2925 | T6: =Q6+R6 -> 23125.316
A7: 1 | B7: 1 | C7: 6 | D7: yes | E7: 15 | F7: 0 | G7: 3778 | H7: =G7/E7 -> 251.86667 | I7: 0.042 | J7: 0.358 | K7: 0.055 | L7: 0.413 | M7: ALL (including NEW) PRUNING | P7: 6 | Q7: =AVERAGE(H202:H235) -> 35106.65 | R7: =STDEV(H202:H235) -> 15765.52 | S7: =Q7-R7 -> 19341.13 | T7: =Q7+R7 -> 50872.17
A8: 1 | B8: 1 | C8: 7 | D8: yes | E8: 16 | F8: 0 | G8: 3903 | H8: =G8/E8 -> 243.9375 | I8: 0.052 | J8: 0.401 | K8: 0.064 | L8: 0.465 | M8: ALL (including NEW) PRUNING
A9: 1 | B9: 1 | C9: 8 | D9: yes | E9: 24 | F9: 0.001 | G9: 5891 | H9: =G9/E9 -> 245.45833 | I9: 0.201 | J9: 0.337 | K9: 0.221 | L9: 0.559 | M9: ALL (including NEW) PRUNING
A10: 1 | B10: 1 | C10: 9 | D10: crit_point_dist: 2.313, grid_dist: 2.52, exact_dist: 2.52 | E10: 27 | F10: 0.007 | G10: 7888 | H10: =G10/E10 -> 292.14815 | I10: 0.393 | J10: 0.394 | K10: 0.419 | L10: 0.813 | M10: ALL (including NEW) PRUNING
A11: 1 | B11: 1 | C11: 10 | D11: yes | E11: 21 | F11: 0.001 | G11: 6584 | H11: =G11/E11 -> 313.52381 | I11: 0.1 | J11: 0.377 | K11: 0.121 | L11: 0.498 | M11: ALL (including NEW) PRUNING
A12: 1 | B12: 1 | C12: 11 | D12: crit_point_dist: 1.743, grid_dist: 1.853, exact_dist: 3.191 | E12: 18 | F12: 0.001 | G12: 6529 | H12: =G12/E12 -> 362.72222 | I12: 0.391 | J12: 0.355 | K12: 0.414 | L12: 0.769 | M12: ALL (including NEW) PRUNING
A13: 1 | B13: 1 | C13: 12 | D13: yes | E13: 19 | F13: 0 | G13: 4827 | H13: =G13/E13 -> 254.05263 | I13: 0.054 | J13: 0.408 | K13: 0.072 | L13: 0.48 | M13: ALL (including NEW) PRUNING
A14: 1 | B14: 1 | C14: 13 | D14: yes | E14: 15 | F14: 0 | G14: 3210 | H14: =G14/E14 -> 214 | I14: 0.041 | J14: 0.305 | K14: 0.052 | L14: 0.356 | M14: ALL (including NEW) PRUNING
A15: 1 | B15: 1 | C15: 14 | D15: yes | E15: 15 | F15: 0 | G15: 3370 | H15: =G15/E15 -> 224.66667 | I15: 0.042 | J15: 0.288 | K15: 0.053 | L15: 0.342 | M15: ALL (including NEW) PRUNING
A16: 1 | B16: 1 | C16: 15 | D16: yes | E16: 15 | F16: 0 | G16: 3438 | H16: =G16/E16 -> 229.2 | I16: 0.029 | J16: 0.381 | K16: 0.043 | L16: 0.423 | M16: ALL (including NEW) PRUNING
A17: 1 | B17: 1 | C17: 16 | D17: yes | E17: 21 | F17: 0.001 | G17: 3333 | H17: =G17/E17 -> 158.71429 | I17: 0.165 | J17: 0.265 | K17: 0.177 | L17: 0.442 | M17: ALL (including NEW) PRUNING
A18: 1 | B18: 1 | C18: 17 | D18: yes | E18: 15 | F18: 0 | G18: 2974 | H18: =G18/E18 -> 198.26667 | I18: 0.032 | J18: 0.284 | K18: 0.043 | L18: 0.327 | M18: ALL (including NEW) PRUNING
A19: 1 | B19: 1 | C19: 18 | D19: yes | E19: 20 | F19: 0 | G19: 3602 | H19: =G19/E19 -> 180.1 | I19: 0.04 | J19: 0.489 | K19: 0.051 | L19: 0.54 | M19: ALL (including NEW) PRUNING
... A235: 3 | B235: 3 | C235: 7 | D235: crit_point_dist: 3.195, grid_dist: 2.453, exact_dist: 3.256 | E235: 1407 | F235: 0.178 | G235: 73584670 | H235: =G235/E235 -> 52298.984 | I235: 5399.153 | J235: 44.218 | K235: 5749.838 | L235: 5794.083 | M235: ALL (including NEW) PRUNING
A236: 1 | B236: 1 | C236: 1 | D236: yes | E236: 16 | F236: 0.005 | G236: 48721 | H236: =G236/E236 -> 3045.0625 | I236: 0.546 | J236: 0.723 | K236: 0.772 | L236: 1.495 | M236: NO PRUNING WHATSOEVER | O236: time_bneck is subset of time_match_dist
A237: 1 | B237: 1 | C237: 2 | D237: yes | E237: 20 | F237: 0.027 | G237: 45932 | H237: =G237/E237 -> 2296.6 | I237: 0.645 | J237: 0.703 | K237: 0.852 | L237: 1.555 | M237: NO PRUNING WHATSOEVER
A238: 1 | B238: 1 | C238: 3 | D238: yes | E238: 27 | F238: 0.081 | G238: 61515 | H238: =G238/E238 -> 2278.3333 | I238: 1.534 | J238: 0.847 | K238: 1.835 | L238: 2.682 | M238: NO PRUNING WHATSOEVER
A239: 1 | B239: 1 | C239: 4 | D239: yes | E239: 21 | F239: 0.084 | G239: 55326 | H239: =G239/E239 -> 2634.5714 | I239: 1.622 | J239: 0.882 | K239: 1.867 | L239: 2.749 | M239: NO PRUNING WHATSOEVER
A240: 1 | B240: 1 | C240: 5 | D240: yes | E240: 18 | F240: 0.082 | G240: 34310 | H240: =G240/E240 -> 1906.1111 | I240: 0.341 | J240: 1.009 | K240: 0.511 | L240: 1.52 | M240: NO PRUNING WHATSOEVER
A241: 1 | B241: 1 | C241: 6 | D241: yes | E241: 15 | F241: 0.029 | G241: 63525 | H241: =G241/E241 -> 4235 | I241: 0.637 | J241: 0.738 | K241: 0.948 | L241: 1.686 | M241: NO PRUNING WHATSOEVER
A242: 1 | B242: 1 | C242: 7 | D242: yes | E242: 16 | F242: 0.03 | G242: 49323 | H242: =G242/E242 -> 3082.6875 | I242: 0.588 | J242: 0.75 | K242: 0.813 | L242: 1.563 | M242: NO PRUNING WHATSOEVER
A243: 1 | B243: 1 | C243: 8 | D243: yes | E243: 24 | F243: 0.016 | G243: 55880 | H243: =G243/E243 -> 2328.3333 | I243: 1.612 | J243: 0.599 | K243: 1.855 | L243: 2.454 | M243: NO PRUNING WHATSOEVER
A244: 1 | B244: 1 | C244: 9 | D244: crit_point_dist: 2.313, grid_dist: 2.52, exact_dist: 2.52 | E244: 27 | F244: 0.021 | G244: 58827 | H244: =G244/E244 -> 2178.7778 | I244: 2.62 | J244: 0.582 | K244: 2.903 | L244: 3.485 | M244: NO PRUNING WHATSOEVER
A245: 1 | B245: 1 | C245: 10 | D245: yes | E245: 21 | F245: 0.005 | G245: 56334 | H245: =G245/E245 -> 2682.5714 | I245: 0.812 | J245: 0.582 | K245: 1.06 | L245: 1.642 | M245: NO PRUNING WHATSOEVER
A246: 1 | B246: 1 | C246: 11 | D246: crit_point_dist: 1.743, grid_dist: 1.853, exact_dist: 3.191 | E246: 18 | F246: 0.006 | G246: 58631 | H246: =G246/E246 -> 3257.2778 | I246: 3.246 | J246: 0.589 | K246: 3.537 | L246: 4.126 | M246: NO PRUNING WHATSOEVER
A247: 1 | B247: 1 | C247: 12 | D247: yes | E247: 19 | F247: 0.005 | G247: 61263 | H247: =G247/E247 -> 3224.3684 | I247: 0.652 | J247: 0.624 | K247: 0.959 | L247: 1.583 | M247: NO PRUNING WHATSOEVER
A248: 1 | B248: 1 | C248: 13 | D248: yes | E248: 15 | F248: 0.017 | G248: 55798 | H248: =G248/E248 -> 3719.8667 | I248: 0.612 | J248: 0.643 | K248: 0.865 | L248: 1.508 | M248: NO PRUNING WHATSOEVER
... A703: 3 | B703: 3 | C703: 7 | D703: crit_point_dist: 3.195, grid_dist: 2.453, exact_dist: 3.256 | E703: 1407 | F703: 0.196 | G703: 125174679 | H703: =G703/E703 -> 88965.657 | I703: 9237.13 | J703: 69.157 | K703: 9729.336 | L703: 9798.507 | M703: ONLY OLD PRUNING

Sheet focus on ratio all lines vs cri
A1: M | B1: N | C1: MN | D1: seed | E1: match | F1: crit_pt_lines_counted | G1: time_crit_pts | H1: exact_lines_counted | I1: ratio all over critical lines | J1: time_bneck | K1: time_switch | L1: time_match_dist | M1: total_exact_time | N1: prune
A2: 1 | B2: 5 | C2: =A2*B2 -> 5 | D2: 1 | E2: yes | F2: 1378 | G2: 0.142 | H2: 50110154 | I2: 1784.203 | J2: 33.5 | K2: 2014.138 | L2: 2047.652 | M2: ALL (including NEW) PRUNING | P2: M+N | Q2: mean
A3: 1 | B3: 5 | C3: =A3*B3 -> 5 | D3: 2 | E3: yes | F3: 1004 | G3: 0.048 | H3: 38185496 | I3: 1670.18 | J3: 43.303 | K3: 1844.861 | L3: 1888.165 | M3: ALL (including NEW) PRUNING | P3: 1+5 | Q3: =AVERAGE(I2:I15) -> 1941.4922
A4: 1 | B4: 5 | C4: =A4*B4 -> 5 | D4: 3 | E4: yes | F4: 1779 | G4: 0.157 | H4: 10762090 | I4: 623.451 | J4: 12.927 | K4: 661.851 | L4: 674.791 | M4: ALL (including NEW) PRUNING | P4: 2+4 | Q4: =AVERAGE(I16:I29) -> 2626.1072
A5: 1 | B5: 5 | C5: =A5*B5 -> 5 | D5: 4 | E5: crit_point_dist: 3.647, grid_dist: 2.451, exact_dist: 3.647 | F5: 1380 | G5: 0.168 | H5: 70649819 | I5: 5088.096 | J5: 46.58 | K5: 5435.231 | L5: 5481.828 | M5: ALL (including NEW) PRUNING | P5: 3+3 | Q5: =AVERAGE(I30:I35) -> 3313.3257
A6: 1 | B6: 5 | C6: =A6*B6 -> 5 | D6: 5 | E6: yes | F6: 1216 | G6: 0.046 | H6: 13532634 | I6: 417.216 | J6: 21.029 | K6: 475.16 | L6: 496.189 | M6: ALL (including NEW) PRUNING
A7: 1 | B7: 5 | C7: =A7*B7 -> 5 | D7: 6 | E7: yes | F7: 1259 | G7: 0.044 | H7: 51926183 | I7: 1521.739 | J7: 40.931 | K7: 1770.195 | L7: 1811.126 | M7: ALL (including NEW) PRUNING
A8: 1 | B8: 5 | C8: =A8*B8 -> 5 | D8: 7 | E8: yes | F8: 1407 | G8: 0.071 | H8: 30697413 | I8: 1283.475 | J8: 26.494 | K8: 1413.28 | L8: 1439.798 | M8: ALL (including NEW) PRUNING
A9: 5 | B9: 1 | C9: =A9*B9 -> 5 | D9: 1 | E9: yes | F9: 1378 | G9: 0.156 | H9: 49595108 | I9: 2403.094 | J9: 34.633 | K9: 2630.558 | L9: 2665.209 | M9: ALL (including NEW) PRUNING
A10: 5 | B10: 1 | C10: =A10*B10 -> 5 | D10: 2 | E10: yes | F10: 1004 | G10: 0.039 | H10: 40577557 | I10: 1321.098 | J10: 44.653 | K10: 1499.466 | L10: 1544.119 | M10: ALL (including NEW) PRUNING
A11: 5 | B11: 1 | C11: =A11*B11 -> 5 | D11: 3 | E11: yes | F11: 1779 | G11: 0.125 | H11: 10668148 | I11: 410.027 | J11: 14.292 | K11: 445.323 | L11: 459.675 | M11: ALL (including NEW) PRUNING
A12: 5 | B12: 1 | C12: =A12*B12 -> 5 | D12: 4 | E12: yes | F12: 1380 | G12: 0.261 | H12: 39942162 | I12: 1754.257 | J12: 29.324 | K12: 1939.262 | L12: 1968.607 | M12: ALL (including NEW) PRUNING
A13: 5 | B13: 1 | C13: =A13*B13 -> 5 | D13: 5 | E13: yes | F13: 1216 | G13: 0.139 | H13: 15689529 | I13: 1118.092 | J13: 20.087 | K13: 1183.974 | L13: 1204.092 | M13: ALL (including NEW) PRUNING
A14: 5 | B14: 1 | C14: =A14*B14 -> 5 | D14: 6 | E14: yes | F14: 1259 | G14: 0.114 | H14: 58594280 | I14: 2801.388 | J14: 46.455 | K14: 3081.986 | L14: 3128.459 | M14: ALL (including NEW) PRUNING
A15: 5 | B15: 1 | C15: =A15*B15 -> 5 | D15: 7 | E15: yes | F15: 1407 | G15: 0.156 | H15: 61789380 | I15: 4984.575 | J15: 37.71 | K15: 5279.913 | L15: 5317.625 | M15: ALL (including NEW) PRUNING
A16: 2 | B16: 4 | C16: =A16*B16 -> 8 | D16: 1 | E16: yes | F16: 1378 | G16: 0.174 | H16: 55569316 | I16: 3752.682 | J16: 36.74 | K16: 4000.458 | L16: 4037.22 | M16: ALL (including NEW) PRUNING
A17: 2 | B17: 4 | C17: =A17*B17 -> 8 | D17: 2 | E17: yes | F17: 1004 | G17: 0.053 | H17: 50902943 | I17: 2365.821 | J17: 51.409 | K17: 2587.518 | L17: 2638.928 | M17: ALL (including NEW) PRUNING
... A35: 3 | B35: 3 | C35: =A35*B35 -> 9 | D35: 7 | E35: crit_point_dist: 3.195, grid_dist: 2.453, exact_dist: 3.256 | F35: 1407 | G35: 0.178 | H35: 73584670 | I35: 5399.153 | J35: 44.218 | K35: 5749.838 | L35: 5794.083 | M35: ALL (including NEW) PRUNING

Sheet graphpruningtime
A1: M + N | B1: All pruning | C1: Old pruning | D1: No pruning
A2: =IFERROR(__xludf.DUMMYFUNCTION("FILTER(dardel_experiment_results!A2:A1001+dardel_experiment_results!B2:B1001, dardel_experiment_results!L2:L1001=""ALL (including NEW) PRUNING"") "),2) -> 2 | B2: =IFERROR(__xludf.DUMMYFUNCTION("FILTER(ABS(LOG(dardel_experiment_results!K2:K1001,10)), dardel_experiment_results!L2:L1001=""ALL (including NEW) PRUNING"") "),0.0899094544059318) -> 0.089909454 | C2: =IFERROR(__xludf.DUMMYFUNCTION("FILTER(ABS(LOG(dardel_experiment_results!K2:K1001,10)), dardel_experiment_results!L2:L1001=""ONLY OLD PRUNING"") "),0.0501222959631252) -> 0.050122296 | D2: =IFERROR(__xludf.DUMMYFUNCTION("FILTER(ABS(LOG(dardel_experiment_results!K2:K1001,10)), dardel_experiment_results!L2:L1001=""NO PRUNING WHATSOEVER"") "),0.542202782434028) -> 0.54220278
A3: =IFERROR(__xludf.DUMMYFUNCTION("""COMPUTED_VALUE"""),2) -> 2 | B3: =IFERROR(__xludf.DUMMYFUNCTION("""COMPUTED_VALUE"""),0.114073660198568) -> 0.11407366 | C3: =IFERROR(__xludf.DUMMYFUNCTION("""COMPUTED_VALUE"""),0.055024091587952) -> 0.055024092 | D3: =IFERROR(__xludf.DUMMYFUNCTION("""COMPUTED_VALUE"""),0.615529223637132) -> 0.61552922
A4: =IFERROR(__xludf.DUMMYFUNCTION("""COMPUTED_VALUE"""),3) -> 3 | B4: =IFERROR(__xludf.DUMMYFUNCTION("""COMPUTED_VALUE"""),1.12635872706926) -> 1.1263587 | C4: =IFERROR(__xludf.DUMMYFUNCTION("""COMPUTED_VALUE"""),1.53619216781264) -> 1.5361922 | D4: =IFERROR(__xludf.DUMMYFUNCTION("""COMPUTED_VALUE"""),2.20804611916638) -> 2.2080461
A5: =IFERROR(__xludf.DUMMYFUNCTION("""COMPUTED_VALUE"""),3) -> 3 | B5: =IFERROR(__xludf.DUMMYFUNCTION("""COMPUTED_VALUE"""),1.2001936371412) -> 1.2001936 | C5: =IFERROR(__xludf.DUMMYFUNCTION("""COMPUTED_VALUE"""),1.27455038490953) -> 1.2745504 | D5: =IFERROR(__xludf.DUMMYFUNCTION("""COMPUTED_VALUE"""),1.93239765500346) -> 1.9323977
A6: =IFERROR(__xludf.DUMMYFUNCTION("""COMPUTED_VALUE"""),3) -> 3 | B6: =IFERROR(__xludf.DUMMYFUNCTION("""COMPUTED_VALUE"""),1.23603314711763) -> 1.2360331 | C6: =IFERROR(__xludf.DUMMYFUNCTION("""COMPUTED_VALUE"""),1.52043112602154) -> 1.5204311 | D6: =IFERROR(__xludf.DUMMYFUNCTION("""COMPUTED_VALUE"""),2.27496562453928) -> 2.2749656
A7: =IFERROR(__xludf.DUMMYFUNCTION("""COMPUTED_VALUE"""),4) -> 4 | B7: =IFERROR(__xludf.DUMMYFUNCTION("""COMPUTED_VALUE"""),2.47444064016599) -> 2.4744406 | C7: =IFERROR(__xludf.DUMMYFUNCTION("""COMPUTED_VALUE"""),2.58571559121331) -> 2.5857156 | D7: =IFERROR(__xludf.DUMMYFUNCTION("""COMPUTED_VALUE"""),3.40024364004358) -> 3.4002436
A8: =IFERROR(__xludf.DUMMYFUNCTION("""COMPUTED_VALUE"""),4) -> 4 | B8: =IFERROR(__xludf.DUMMYFUNCTION("""COMPUTED_VALUE"""),2.25013200375463) -> 2.250132 | C8: =IFERROR(__xludf.DUMMYFUNCTION("""COMPUTED_VALUE"""),2.66881068375575) -> 2.6688107 | D8: =IFERROR(__xludf.DUMMYFUNCTION("""COMPUTED_VALUE"""),3.32144949804915) -> 3.3214495
A9: =IFERROR(__xludf.DUMMYFUNCTION("""COMPUTED_VALUE"""),4) -> 4 | B9: =IFERROR(__xludf.DUMMYFUNCTION("""COMPUTED_VALUE"""),2.19280154130617) -> 2.1928015 | C9: =IFERROR(__xludf.DUMMYFUNCTION("""COMPUTED_VALUE"""),2.27529983464149) -> 2.2752998 | D9: =IFERROR(__xludf.DUMMYFUNCTION("""COMPUTED_VALUE"""),2.97257539395023) -> 2.9725754
A10: =IFERROR(__xludf.DUMMYFUNCTION("""COMPUTED_VALUE"""),4) -> 4 | B10: =IFERROR(__xludf.DUMMYFUNCTION("""COMPUTED_VALUE"""),2.233387053387) -> 2.2333871 | C10: =IFERROR(__xludf.DUMMYFUNCTION("""COMPUTED_VALUE"""),2.51128562787917) -> 2.5112856 | D10: =IFERROR(__xludf.DUMMYFUNCTION("""COMPUTED_VALUE"""),3.28316300153736) -> 3.283163
A11: =IFERROR(__xludf.DUMMYFUNCTION("""COMPUTED_VALUE"""),5) -> 5 | B11: =IFERROR(__xludf.DUMMYFUNCTION("""COMPUTED_VALUE"""),3.17215848599349) -> 3.1721585 | C11: =IFERROR(__xludf.DUMMYFUNCTION("""COMPUTED_VALUE"""),3.28306569580687) -> 3.2830657 | D11: =IFERROR(__xludf.DUMMYFUNCTION("""COMPUTED_VALUE"""),4.11667122337392) -> 4.1166712
A12: =IFERROR(__xludf.DUMMYFUNCTION("""COMPUTED_VALUE"""),5) -> 5 | B12: =IFERROR(__xludf.DUMMYFUNCTION("""COMPUTED_VALUE"""),2.88289663092229) -> 2.8828966 | C12: =IFERROR(__xludf.DUMMYFUNCTION("""COMPUTED_VALUE"""),3.29499059012067) -> 3.2949906 | D12: =IFERROR(__xludf.DUMMYFUNCTION("""COMPUTED_VALUE"""),4.10836352388492) -> 4.1083635
A13: =IFERROR(__xludf.DUMMYFUNCTION("""COMPUTED_VALUE"""),5) -> 5 | B13: =IFERROR(__xludf.DUMMYFUNCTION("""COMPUTED_VALUE"""),2.925293006881) -> 2.925293 | C13: =IFERROR(__xludf.DUMMYFUNCTION("""COMPUTED_VALUE"""),3.11122923440128) -> 3.1112292 | D13: =IFERROR(__xludf.DUMMYFUNCTION("""COMPUTED_VALUE"""),3.82079060952529) -> 3.8207906
A14: =IFERROR(__xludf.DUMMYFUNCTION("""COMPUTED_VALUE"""),5) -> 5 | B14: =IFERROR(__xludf.DUMMYFUNCTION("""COMPUTED_VALUE"""),2.99792825893334) -> 2.9979283 | C14: =IFERROR(__xludf.DUMMYFUNCTION("""COMPUTED_VALUE"""),3.33653317744223) -> 3.3365332 | D14: =IFERROR(__xludf.DUMMYFUNCTION("""COMPUTED_VALUE"""),4.07947118557425) -> 4.0794712
A15: =IFERROR(__xludf.DUMMYFUNCTION("""COMPUTED_VALUE"""),5) -> 5 | B15: =IFERROR(__xludf.DUMMYFUNCTION("""COMPUTED_VALUE"""),2.98782172524646) -> 2.9878217 | C15: =IFERROR(__xludf.DUMMYFUNCTION("""COMPUTED_VALUE"""),3.18803705500689) -> 3.1880371 | D15: =IFERROR(__xludf.DUMMYFUNCTION("""COMPUTED_VALUE"""),3.98967420450192) -> 3.9896742
A16: =IFERROR(__xludf.DUMMYFUNCTION("""COMPUTED_VALUE"""),5) -> 5 | B16: =IFERROR(__xludf.DUMMYFUNCTION("""COMPUTED_VALUE"""),2.30291940368216) -> 2.3029194 | C16: =IFERROR(__xludf.DUMMYFUNCTION("""COMPUTED_VALUE"""),2.87146726771718) -> 2.8714673 | D16: =IFERROR(__xludf.DUMMYFUNCTION("""COMPUTED_VALUE"""),3.72415531566599) -> 3.7241553
A17: =IFERROR(__xludf.DUMMYFUNCTION("""COMPUTED_VALUE"""),6) -> 6 | B17: =IFERROR(__xludf.DUMMYFUNCTION("""COMPUTED_VALUE"""),3.73892540482209) -> 3.7389254 | C17: =IFERROR(__xludf.DUMMYFUNCTION("""COMPUTED_VALUE"""),3.90066868106392) -> 3.9006687 | D17: =IFERROR(__xludf.DUMMYFUNCTION("""COMPUTED_VALUE"""),4.73345459463215) -> 4.7334546
A18: =IFERROR(__xludf.DUMMYFUNCTION("""COMPUTED_VALUE"""),2) -> 2 | B18: =IFERROR(__xludf.DUMMYFUNCTION("""COMPUTED_VALUE"""),0.417936637088291) -> 0.41793664 | C18: =IFERROR(__xludf.DUMMYFUNCTION("""COMPUTED_VALUE"""),0.238824186844268) -> 0.23882419 | D18: =IFERROR(__xludf.DUMMYFUNCTION("""COMPUTED_VALUE"""),0.174641192660448) -> 0.17464119
A19: =IFERROR(__xludf.DUMMYFUNCTION("""COMPUTED_VALUE"""),2) -> 2 | B19: =IFERROR(__xludf.DUMMYFUNCTION("""COMPUTED_VALUE"""),0.27572413039921) -> 0.27572413 | C19: =IFERROR(__xludf.DUMMYFUNCTION("""COMPUTED_VALUE"""),0.224753740259763) -> 0.22475374 | D19: =IFERROR(__xludf.DUMMYFUNCTION("""COMPUTED_VALUE"""),0.191730393362856) -> 0.19173039
A20: =IFERROR(__xludf.DUMMYFUNCTION("""COMPUTED_VALUE"""),2) -> 2 | B20: =IFERROR(__xludf.DUMMYFUNCTION("""COMPUTED_VALUE"""),0.244125144327508) -> 0.24412514 | C20: =IFERROR(__xludf.DUMMYFUNCTION("""COMPUTED_VALUE"""),0.133712660915805) -> 0.13371266 | D20: =IFERROR(__xludf.DUMMYFUNCTION("""COMPUTED_VALUE"""),0.42845877351558) -> 0.42845877
A21: =IFERROR(__xludf.DUMMYFUNCTION("""COMPUTED_VALUE"""),2) -> 2 | B21: =IFERROR(__xludf.DUMMYFUNCTION("""COMPUTED_VALUE"""),0.209714835966758) -> 0.20971484 | C21: =IFERROR(__xludf.DUMMYFUNCTION("""COMPUTED_VALUE"""),0.136677139879544) -> 0.13667714 | D21: =IFERROR(__xludf.DUMMYFUNCTION("""COMPUTED_VALUE"""),0.439174739843468) -> 0.43917474
A22: =IFERROR(__xludf.DUMMYFUNCTION("""COMPUTED_VALUE"""),2) -> 2 | B22: =IFERROR(__xludf.DUMMYFUNCTION("""COMPUTED_VALUE"""),0.26921772433361) -> 0.26921772 | C22: =IFERROR(__xludf.DUMMYFUNCTION("""COMPUTED_VALUE"""),0.22767829327708) -> 0.22767829 | D22: =IFERROR(__xludf.DUMMYFUNCTION("""COMPUTED_VALUE"""),0.181843587944772) -> 0.18184359
A23: =IFERROR(__xludf.DUMMYFUNCTION("""COMPUTED_VALUE"""),2) -> 2 | B23: =IFERROR(__xludf.DUMMYFUNCTION("""COMPUTED_VALUE"""),0.384049948343599) -> 0.38404995 | C23: =IFERROR(__xludf.DUMMYFUNCTION("""COMPUTED_VALUE"""),0.328827157284916) -> 0.32882716 | D23: =IFERROR(__xludf.DUMMYFUNCTION("""COMPUTED_VALUE"""),0.226857570288723) -> 0.22685757
A24: =IFERROR(__xludf.DUMMYFUNCTION("""COMPUTED_VALUE"""),2) -> 2 | B24: =IFERROR(__xludf.DUMMYFUNCTION("""COMPUTED_VALUE"""),0.332547047110046) -> 0.33254705 | C24: =IFERROR(__xludf.DUMMYFUNCTION("""COMPUTED_VALUE"""),0.255707016877323) -> 0.25570702 | D24: =IFERROR(__xludf.DUMMYFUNCTION("""COMPUTED_VALUE"""),0.193958978019186) -> 0.19395898
A25: =IFERROR(__xludf.DUMMYFUNCTION("""COMPUTED_VALUE"""),2) -> 2 | B25: =IFERROR(__xludf.DUMMYFUNCTION("""COMPUTED_VALUE"""),0.252588192113576) -> 0.25258819 | C25: =IFERROR(__xludf.DUMMYFUNCTION("""COMPUTED_VALUE"""),0.114638779968488) -> 0.11463878 | D25: =IFERROR(__xludf.DUMMYFUNCTION("""COMPUTED_VALUE"""),0.389874558390985) -> 0.38987456
A26: =IFERROR(__xludf.DUMMYFUNCTION("""COMPUTED_VALUE"""),2) -> 2 | B26: =IFERROR(__xludf.DUMMYFUNCTION("""COMPUTED_VALUE"""),0.302770657240282) -> 0.30277066 | C26: =IFERROR(__xludf.DUMMYFUNCTION("""COMPUTED_VALUE"""),0.224753740259763) -> 0.22475374 | D26: =IFERROR(__xludf.DUMMYFUNCTION("""COMPUTED_VALUE"""),0.215373152783421) -> 0.21537315
A27: =IFERROR(__xludf.DUMMYFUNCTION("""COMPUTED_VALUE"""),2) -> 2 | B27: =IFERROR(__xludf.DUMMYFUNCTION("""COMPUTED_VALUE"""),0.318758762624412) -> 0.31875876 | C27: =IFERROR(__xludf.DUMMYFUNCTION("""COMPUTED_VALUE"""),0.27901425584626) -> 0.27901426 | D27: =IFERROR(__xludf.DUMMYFUNCTION("""COMPUTED_VALUE"""),0.199480914862355) -> 0.19948091
A28: =IFERROR(__xludf.DUMMYFUNCTION("""COMPUTED_VALUE"""),2) -> 2 | B28: =IFERROR(__xludf.DUMMYFUNCTION("""COMPUTED_VALUE"""),0.448550002027124) -> 0.44855 | C28: =IFERROR(__xludf.DUMMYFUNCTION("""COMPUTED_VALUE"""),0.27572413039921) -> 0.27572413 | D28: =IFERROR(__xludf.DUMMYFUNCTION("""COMPUTED_VALUE"""),0.178401341533755) -> 0.17840134
A29: =IFERROR(__xludf.DUMMYFUNCTION("""COMPUTED_VALUE"""),2) -> 2 | B29: =IFERROR(__xludf.DUMMYFUNCTION("""COMPUTED_VALUE"""),0.465973893943864) -> 0.46597389 | C29: =IFERROR(__xludf.DUMMYFUNCTION("""COMPUTED_VALUE"""),0.281498311132725) -> 0.28149831 | D29: =IFERROR(__xludf.DUMMYFUNCTION("""COMPUTED_VALUE"""),0.184691430817598) -> 0.18469143
A30: =IFERROR(__xludf.DUMMYFUNCTION("""COMPUTED_VALUE"""),2) -> 2 | B30: =IFERROR(__xludf.DUMMYFUNCTION("""COMPUTED_VALUE"""),0.373659632624957) -> 0.37365963 | C30: =IFERROR(__xludf.DUMMYFUNCTION("""COMPUTED_VALUE"""),0.331614083309999) -> 0.33161408 | D30: =IFERROR(__xludf.DUMMYFUNCTION("""COMPUTED_VALUE"""),0.169086357487022) -> 0.16908636
A31: =IFERROR(__xludf.DUMMYFUNCTION("""COMPUTED_VALUE"""),2) -> 2 | B31: =IFERROR(__xludf.DUMMYFUNCTION("""COMPUTED_VALUE"""),0.354577730650908) -> 0.35457773 | C31: =IFERROR(__xludf.DUMMYFUNCTION("""COMPUTED_VALUE"""),0.0447934624580582) -> 0.044793462 | D31: =IFERROR(__xludf.DUMMYFUNCTION("""COMPUTED_VALUE"""),0.545554507234065) -> 0.54555451
A32: =IFERROR(__xludf.DUMMYFUNCTION("""COMPUTED_VALUE"""),2) -> 2 | B32: =IFERROR(__xludf.DUMMYFUNCTION("""COMPUTED_VALUE"""),0.485452247339713) -> 0.48545225 | C32: =IFERROR(__xludf.DUMMYFUNCTION("""COMPUTED_VALUE"""),0.289882634888183) -> 0.28988263 | D32: =IFERROR(__xludf.DUMMYFUNCTION("""COMPUTED_VALUE"""),0.171141151028382) -> 0.17114115
A33: =IFERROR(__xludf.DUMMYFUNCTION("""COMPUTED_VALUE"""),2) -> 2 | B33: =IFERROR(__xludf.DUMMYFUNCTION("""COMPUTED_VALUE"""),0.267606240177031) -> 0.26760624 | C33: =IFERROR(__xludf.DUMMYFUNCTION("""COMPUTED_VALUE"""),0.22112552799726) -> 0.22112553 | D33: =IFERROR(__xludf.DUMMYFUNCTION("""COMPUTED_VALUE"""),0.188084373714938) -> 0.18808437
A34: =IFERROR(__xludf.DUMMYFUNCTION("""COMPUTED_VALUE"""),2) -> 2 | B34: =IFERROR(__xludf.DUMMYFUNCTION("""COMPUTED_VALUE"""),0.39040559077478) -> 0.39040559 | C34: =IFERROR(__xludf.DUMMYFUNCTION("""COMPUTED_VALUE"""),0.283162276700475) -> 0.28316228 | D34: =IFERROR(__xludf.DUMMYFUNCTION("""COMPUTED_VALUE"""),0.231469590430681) -> 0.23146959
A35: =IFERROR(__xludf.DUMMYFUNCTION("""COMPUTED_VALUE"""),2) -> 2 | B35: =IFERROR(__xludf.DUMMYFUNCTION("""COMPUTED_VALUE"""),0.309803919971486) -> 0.30980392 | C35: =IFERROR(__xludf.DUMMYFUNCTION("""COMPUTED_VALUE"""),0.254925208417942) -> 0.25492521 | D35: =IFERROR(__xludf.DUMMYFUNCTION("""COMPUTED_VALUE"""),0.16761267272753) -> 0.16761267
A36: =IFERROR(__xludf.DUMMYFUNCTION("""COMPUTED_VALUE"""),3) -> 3 | B36: =IFERROR(__xludf.DUMMYFUNCTION("""COMPUTED_VALUE"""),0.720903170813457) -> 0.72090317 | C36: =IFERROR(__xludf.DUMMYFUNCTION("""COMPUTED_VALUE"""),1.01707509637605) -> 1.0170751 | D36: =IFERROR(__xludf.DUMMYFUNCTION("""COMPUTED_VALUE"""),1.72077102080463) -> 1.720771
A37: =IFERROR(__xludf.DUMMYFUNCTION("""COMPUTED_VALUE"""),3) -> 3 | B37: =IFERROR(__xludf.DUMMYFUNCTION("""COMPUTED_VALUE"""),0.488409688903198) -> 0.48840969 | C37: =IFERROR(__xludf.DUMMYFUNCTION("""COMPUTED_VALUE"""),0.82288694783415) -> 0.82288695 | D37: =IFERROR(__xludf.DUMMYFUNCTION("""COMPUTED_VALUE"""),1.64332434324819) -> 1.6433243
A38: =IFERROR(__xludf.DUMMYFUNCTION("""COMPUTED_VALUE"""),3) -> 3 | B38: =IFERROR(__xludf.DUMMYFUNCTION("""COMPUTED_VALUE"""),1.32209519286655) -> 1.3220952 | C38: =IFERROR(__xludf.DUMMYFUNCTION("""COMPUTED_VALUE"""),1.59933713299248) -> 1.5993371 | D38: =IFERROR(__xludf.DUMMYFUNCTION("""COMPUTED_VALUE"""),2.25967270406376) -> 2.2596727
A39: =IFERROR(__xludf.DUMMYFUNCTION("""COMPUTED_VALUE"""),3) -> 3 | B39: =IFERROR(__xludf.DUMMYFUNCTION("""COMPUTED_VALUE"""),0.905741927391601) -> 0.90574193 | C39: =IFERROR(__xludf.DUMMYFUNCTION("""COMPUTED_VALUE"""),1.0562185812723) -> 1.0562186 | D39: =IFERROR(__xludf.DUMMYFUNCTION("""COMPUTED_VALUE"""),1.86173747221544) -> 1.8617375
A40: =IFERROR(__xludf.DUMMYFUNCTION("""COMPUTED_VALUE"""),3) -> 3 | B40: =IFERROR(__xludf.DUMMYFUNCTION("""COMPUTED_VALUE"""),0.665580991017953) -> 0.66558099 | C40: =IFERROR(__xludf.DUMMYFUNCTION("""COMPUTED_VALUE"""),0.792951708250132) -> 0.79295171 | D40: =IFERROR(__xludf.DUMMYFUNCTION("""COMPUTED_VALUE"""),1.56362345369003) -> 1.5636235
...

Sheet graphtime
A1: {=IF( ISNUMBER(dardel_experiment_results!F1:F1000), IF(dardel_experiment_results!F1:F1000 > 0, LOG(dardel_experiment_results!F1:F1000), ), dardel_experiment_results!F1:F1000 )} -> time_crit_pts | B1: {=IF( ISNUMBER(dardel_experiment_results!H1:H1000), IF(dardel_experiment_results!H1:H1000 > 0, ABS(LOG(dardel_experiment_results!H1:H1000)), ), dardel_experiment_results!H1:H1000 )} -> time_bneck | C1: {=IF( ISNUMBER(dardel_experiment_results!I1:I1000), IF(dardel_experiment_results!I1:I1000 > 0, ABS(LOG(dardel_experiment_results!I1:I1000)), ), dardel_experiment_results!I1:I1000 )} -> time_switch | D1: {=IF( ISNUMBER(dardel_experiment_results!J1:J1000), IF(dardel_experiment_results!J1:J1000 > 0, ABS(LOG(dardel_experiment_results!J1:J1000)), ), dardel_experiment_results!J1:J1000 )} -> time_match_dist | E1: {=IF( ISNUMBER(dardel_experiment_results!K1:K1000), IF(dardel_experiment_results!K1:K1000 > 0, ABS(LOG(dardel_experiment_results!K1:K1000)), ), dardel_experiment_results!K1:K1000 )} -> total_exact_time
A2: -2.154902 | B2: 0.40560745 | C2: 0.40450378 | D2: 0.37778598 | E2: 0.089909454
A3: -3 | B3: 0.40782324 | C3: 0.44977165 | D3: 0.38299966 | E3: 0.11407366
A4: -2.09691 | B4: 1.0381033 | C4: 0.20303289 | D4: 1.0711822 | E4: 1.1263587
A5: -2.30103 | B5: 1.0598662 | C5: 0.43838411 | D5: 1.1176689 | E5: 1.2001936
A6: -2.0457575 | B6: 1.163221 | C6: 0.21058602 | D6: 1.1930132 | E6: 1.2360331
A7: -1.5086383 | B7: 2.4380152 | C7: 0.97767789 | D7: 2.4603776 | E7: 2.4744406
A8: -1.5686362 | B8: 2.2071279 | C8: 0.78653848 | D8: 2.2349347 | E8: 2.250132
A9: -1.8860566 | B9: 2.1080675 | C9: 0.98980565 | D9: 2.1646978 | E9: 2.1928015
A10: -1.6382722 | B10: 2.1859924 | C10: 0.7996162 | D10: 2.217089 | E10: 2.2333871
A11: -1.2924298 | B11: 3.1377743 | C11: 1.3982352 | D11: 3.1647872 | E11: 3.1721585
A12: -1.2924298 | B12: 2.8402755 | C12: 1.1689098 | D12: 2.8744233 | E12: 2.8828966
A13: -1.455932 | B13: 2.8636529 | C13: 1.345609 | D13: 2.9137084 | E13: 2.925293
... A1000: 0 | B1000: 0 | C1000: 0 | D1000: 0 | E1000: 0

Sheet graphpruningnumber_cp
A1: M + N | B1: All pruning | C1: Old pruning | D1: No pruning
A2: =IFERROR(__xludf.DUMMYFUNCTION("FILTER(dardel_experiment_results!A2:A1001+dardel_experiment_results!B2:B1001, dardel_experiment_results!L2:L1001=""ALL (including NEW) PRUNING"") "),2) -> 2 | B2: =IFERROR(__xludf.DUMMYFUNCTION("FILTER(ABS(LOG(dardel_experiment_results!G2:G1001,10)), dardel_experiment_results!L2:L1001=""ALL (including NEW) PRUNING"") "),3.89696690193315) -> 3.8969669 | C2: =IFERROR(__xludf.DUMMYFUNCTION("FILTER(ABS(LOG(dardel_experiment_results!G2:G1001,10)), dardel_experiment_results!L2:L1001=""ONLY OLD PRUNING"") "),3.93490225832231) -> 3.9349023 | D2: =IFERROR(__xludf.DUMMYFUNCTION("FILTER(ABS(LOG(dardel_experiment_results!G2:G1001,10)), dardel_experiment_results!L2:L1001=""NO PRUNING WHATSOEVER"") "),4.76957670124029) -> 4.7695767
A3: =IFERROR(__xludf.DUMMYFUNCTION("""COMPUTED_VALUE"""),2) -> 2 | B3: =IFERROR(__xludf.DUMMYFUNCTION("""COMPUTED_VALUE"""),3.81484666860446) -> 3.8148467 | C3: =IFERROR(__xludf.DUMMYFUNCTION("""COMPUTED_VALUE"""),3.87453979707101) -> 3.8745398 | D3: =IFERROR(__xludf.DUMMYFUNCTION("""COMPUTED_VALUE"""),4.76812730149808) -> 4.7681273
A4: =IFERROR(__xludf.DUMMYFUNCTION("""COMPUTED_VALUE"""),3) -> 3 | B4: =IFERROR(__xludf.DUMMYFUNCTION("""COMPUTED_VALUE"""),5.2415315390156) -> 5.2415315 | C4: =IFERROR(__xludf.DUMMYFUNCTION("""COMPUTED_VALUE"""),5.64536134594061) -> 5.6453613 | D4: =IFERROR(__xludf.DUMMYFUNCTION("""COMPUTED_VALUE"""),6.39331156354219) -> 6.3933116
A5: =IFERROR(__xludf.DUMMYFUNCTION("""COMPUTED_VALUE"""),3) -> 3 | B5: =IFERROR(__xludf.DUMMYFUNCTION("""COMPUTED_VALUE"""),5.51442554864198) -> 5.5144255 | C5: =IFERROR(__xludf.DUMMYFUNCTION("""COMPUTED_VALUE"""),5.58863916061302) -> 5.5886392 | D5: =IFERROR(__xludf.DUMMYFUNCTION("""COMPUTED_VALUE"""),6.37734887687425) -> 6.3773489
A6: =IFERROR(__xludf.DUMMYFUNCTION("""COMPUTED_VALUE"""),3) -> 3 | B6: =IFERROR(__xludf.DUMMYFUNCTION("""COMPUTED_VALUE"""),5.28257000347611) -> 5.28257 | C6: =IFERROR(__xludf.DUMMYFUNCTION("""COMPUTED_VALUE"""),5.56084120628856) -> 5.5608412 | D6: =IFERROR(__xludf.DUMMYFUNCTION("""COMPUTED_VALUE"""),6.41727916590603) -> 6.4172792
A7: =IFERROR(__xludf.DUMMYFUNCTION("""COMPUTED_VALUE"""),4) -> 4 | B7: =IFERROR(__xludf.DUMMYFUNCTION("""COMPUTED_VALUE"""),6.47316686102694) -> 6.4731669 | C7: =IFERROR(__xludf.DUMMYFUNCTION("""COMPUTED_VALUE"""),6.58573531984224) -> 6.5857353 | D7: =IFERROR(__xludf.DUMMYFUNCTION("""COMPUTED_VALUE"""),7.45588134219309) -> 7.4558813
A8: =IFERROR(__xludf.DUMMYFUNCTION("""COMPUTED_VALUE"""),4) -> 4 | B8: =IFERROR(__xludf.DUMMYFUNCTION("""COMPUTED_VALUE"""),6.37208366169784) -> 6.3720837 | C8: =IFERROR(__xludf.DUMMYFUNCTION("""COMPUTED_VALUE"""),6.77637664914066) -> 6.7763766 | D8: =IFERROR(__xludf.DUMMYFUNCTION("""COMPUTED_VALUE"""),7.48261248558313) -> 7.4826125
A9: =IFERROR(__xludf.DUMMYFUNCTION("""COMPUTED_VALUE"""),4) -> 4 | B9: =IFERROR(__xludf.DUMMYFUNCTION("""COMPUTED_VALUE"""),6.58827013777556) -> 6.5882701 | C9: =IFERROR(__xludf.DUMMYFUNCTION("""COMPUTED_VALUE"""),6.6716828622899) -> 6.6716829 | D9: =IFERROR(__xludf.DUMMYFUNCTION("""COMPUTED_VALUE"""),7.43231989592651) -> 7.4323199
A10: =IFERROR(__xludf.DUMMYFUNCTION("""COMPUTED_VALUE"""),4) -> 4 | B10: =IFERROR(__xludf.DUMMYFUNCTION("""COMPUTED_VALUE"""),6.35582473419806) -> 6.3558247 | C10: =IFERROR(__xludf.DUMMYFUNCTION("""COMPUTED_VALUE"""),6.64303565233061) -> 6.6430357 | D10: =IFERROR(__xludf.DUMMYFUNCTION("""COMPUTED_VALUE"""),7.45654644045465) -> 7.4565464
A11: =IFERROR(__xludf.DUMMYFUNCTION("""COMPUTED_VALUE"""),5) -> 5 | B11: =IFERROR(__xludf.DUMMYFUNCTION("""COMPUTED_VALUE"""),7.24046962032813) -> 7.2404696 | C11: =IFERROR(__xludf.DUMMYFUNCTION("""COMPUTED_VALUE"""),7.35793760895219) -> 7.3579376 | D11: =IFERROR(__xludf.DUMMYFUNCTION("""COMPUTED_VALUE"""),8.24392463753145) -> 8.2439246
A12: =IFERROR(__xludf.DUMMYFUNCTION("""COMPUTED_VALUE"""),5) -> 5 | B12: =IFERROR(__xludf.DUMMYFUNCTION("""COMPUTED_VALUE"""),7.04736047143758) -> 7.0473605 | C12: =IFERROR(__xludf.DUMMYFUNCTION("""COMPUTED_VALUE"""),7.44633396727187) -> 7.446334 | D12: =IFERROR(__xludf.DUMMYFUNCTION("""COMPUTED_VALUE"""),8.301128640966) -> 8.3011286
A13: =IFERROR(__xludf.DUMMYFUNCTION("""COMPUTED_VALUE"""),5) -> 5 | B13: =IFERROR(__xludf.DUMMYFUNCTION("""COMPUTED_VALUE"""),7.29639206916079) -> 7.2963921 | C13: =IFERROR(__xludf.DUMMYFUNCTION("""COMPUTED_VALUE"""),7.48141474962838) -> 7.4814147 | D13: =IFERROR(__xludf.DUMMYFUNCTION("""COMPUTED_VALUE"""),8.23616930811176) -> 8.2361693
A14: =IFERROR(__xludf.DUMMYFUNCTION("""COMPUTED_VALUE"""),5) -> 5 | B14: =IFERROR(__xludf.DUMMYFUNCTION("""COMPUTED_VALUE"""),7.14062951537334) -> 7.1406295 | C14: =IFERROR(__xludf.DUMMYFUNCTION("""COMPUTED_VALUE"""),7.4889232180311) -> 7.4889232 | D14: =IFERROR(__xludf.DUMMYFUNCTION("""COMPUTED_VALUE"""),8.25978245265457) -> 8.2597825
A15: =IFERROR(__xludf.DUMMYFUNCTION("""COMPUTED_VALUE"""),5) -> 5 | B15: =IFERROR(__xludf.DUMMYFUNCTION("""COMPUTED_VALUE"""),7.18438061456275) -> 7.1843806 | C15: =IFERROR(__xludf.DUMMYFUNCTION("""COMPUTED_VALUE"""),7.38433099084313) -> 7.384331 | D15: =IFERROR(__xludf.DUMMYFUNCTION("""COMPUTED_VALUE"""),8.28135012296432) -> 8.2813501
A16: =IFERROR(__xludf.DUMMYFUNCTION("""COMPUTED_VALUE"""),5) -> 5 | B16: =IFERROR(__xludf.DUMMYFUNCTION("""COMPUTED_VALUE"""),6.78819836047384) -> 6.7881984 | C16: =IFERROR(__xludf.DUMMYFUNCTION("""COMPUTED_VALUE"""),7.37154332992814) -> 7.3715433 | D16: =IFERROR(__xludf.DUMMYFUNCTION("""COMPUTED_VALUE"""),8.24453364748661) -> 8.2445336
A17: =IFERROR(__xludf.DUMMYFUNCTION("""COMPUTED_VALUE"""),6) -> 6 | B17: =IFERROR(__xludf.DUMMYFUNCTION("""COMPUTED_VALUE"""),7.84911105355326) -> 7.8491111 | C17: =IFERROR(__xludf.DUMMYFUNCTION("""COMPUTED_VALUE"""),8.02120946227424) -> 8.0212095 | D17: =IFERROR(__xludf.DUMMYFUNCTION("""COMPUTED_VALUE"""),8.89097595124526) -> 8.890976
A18: =IFERROR(__xludf.DUMMYFUNCTION("""COMPUTED_VALUE"""),2) -> 2 | B18: =IFERROR(__xludf.DUMMYFUNCTION("""COMPUTED_VALUE"""),3.45545396877862) -> 3.455454 | C18: =IFERROR(__xludf.DUMMYFUNCTION("""COMPUTED_VALUE"""),3.81338080673385) -> 3.8133808 | D18: =IFERROR(__xludf.DUMMYFUNCTION("""COMPUTED_VALUE"""),4.68771619362368) -> 4.6877162
A19: =IFERROR(__xludf.DUMMYFUNCTION("""COMPUTED_VALUE"""),2) -> 2 | B19: =IFERROR(__xludf.DUMMYFUNCTION("""COMPUTED_VALUE"""),3.74186039406526) -> 3.7418604 | C19: =IFERROR(__xludf.DUMMYFUNCTION("""COMPUTED_VALUE"""),3.8483738838446) -> 3.8483739 | D19: =IFERROR(__xludf.DUMMYFUNCTION("""COMPUTED_VALUE"""),4.6621153561528) -> 4.6621154
A20: =IFERROR(__xludf.DUMMYFUNCTION("""COMPUTED_VALUE"""),2) -> 2 | B20: =IFERROR(__xludf.DUMMYFUNCTION("""COMPUTED_VALUE"""),3.81710240425692) -> 3.8171024 | C20: =IFERROR(__xludf.DUMMYFUNCTION("""COMPUTED_VALUE"""),3.94963392379926) -> 3.9496339 | D20: =IFERROR(__xludf.DUMMYFUNCTION("""COMPUTED_VALUE"""),4.78898102834316) -> 4.788981
A21: =IFERROR(__xludf.DUMMYFUNCTION("""COMPUTED_VALUE"""),2) -> 2 | B21: =IFERROR(__xludf.DUMMYFUNCTION("""COMPUTED_VALUE"""),3.82529626443096) -> 3.8252963 | C21: =IFERROR(__xludf.DUMMYFUNCTION("""COMPUTED_VALUE"""),3.88671627411647) -> 3.8867163 | D21: =IFERROR(__xludf.DUMMYFUNCTION("""COMPUTED_VALUE"""),4.74292927240602) -> 4.7429293
A22: =IFERROR(__xludf.DUMMYFUNCTION("""COMPUTED_VALUE"""),2) -> 2 | B22: =IFERROR(__xludf.DUMMYFUNCTION("""COMPUTED_VALUE"""),3.33122478102073) -> 3.3312248 | C22: =IFERROR(__xludf.DUMMYFUNCTION("""COMPUTED_VALUE"""),3.3336487565147) -> 3.3336488 | D22: =IFERROR(__xludf.DUMMYFUNCTION("""COMPUTED_VALUE"""),4.53542071805617) -> 4.5354207
A23: =IFERROR(__xludf.DUMMYFUNCTION("""COMPUTED_VALUE"""),2) -> 2 | B23: =IFERROR(__xludf.DUMMYFUNCTION("""COMPUTED_VALUE"""),3.57726195358581) -> 3.577262 | C23: =IFERROR(__xludf.DUMMYFUNCTION("""COMPUTED_VALUE"""),3.62613497863538) -> 3.626135 | D23: =IFERROR(__xludf.DUMMYFUNCTION("""COMPUTED_VALUE"""),4.8029446737224) -> 4.8029447
A24: =IFERROR(__xludf.DUMMYFUNCTION("""COMPUTED_VALUE"""),2) -> 2 | B24: =IFERROR(__xludf.DUMMYFUNCTION("""COMPUTED_VALUE"""),3.59139855128124) -> 3.5913986 | C24: =IFERROR(__xludf.DUMMYFUNCTION("""COMPUTED_VALUE"""),3.70440792738684) -> 3.7044079 | D24: =IFERROR(__xludf.DUMMYFUNCTION("""COMPUTED_VALUE"""),4.69304948405958) -> 4.6930495
A25: =IFERROR(__xludf.DUMMYFUNCTION("""COMPUTED_VALUE"""),2) -> 2 | B25: =IFERROR(__xludf.DUMMYFUNCTION("""COMPUTED_VALUE"""),3.77018902273599) -> 3.770189 | C25: =IFERROR(__xludf.DUMMYFUNCTION("""COMPUTED_VALUE"""),3.90698115322885) -> 3.9069812 | D25: =IFERROR(__xludf.DUMMYFUNCTION("""COMPUTED_VALUE"""),4.74725639744214) -> 4.7472564
A26: =IFERROR(__xludf.DUMMYFUNCTION("""COMPUTED_VALUE"""),2) -> 2 | B26: =IFERROR(__xludf.DUMMYFUNCTION("""COMPUTED_VALUE"""),3.81848982220421) -> 3.8184898 | C26: =IFERROR(__xludf.DUMMYFUNCTION("""COMPUTED_VALUE"""),3.90074935806107) -> 3.9007494 | D26: =IFERROR(__xludf.DUMMYFUNCTION("""COMPUTED_VALUE"""),4.75077058944326) -> 4.7507706
A27: =IFERROR(__xludf.DUMMYFUNCTION("""COMPUTED_VALUE"""),2) -> 2 | B27: =IFERROR(__xludf.DUMMYFUNCTION("""COMPUTED_VALUE"""),3.68367729881869) -> 3.6836773 | C27: =IFERROR(__xludf.DUMMYFUNCTION("""COMPUTED_VALUE"""),3.73949323078161) -> 3.7394932 | D27: =IFERROR(__xludf.DUMMYFUNCTION("""COMPUTED_VALUE"""),4.78719826004392) -> 4.7871983
A28: =IFERROR(__xludf.DUMMYFUNCTION("""COMPUTED_VALUE"""),2) -> 2 | B28: =IFERROR(__xludf.DUMMYFUNCTION("""COMPUTED_VALUE"""),3.50650503240487) -> 3.506505 | C28: =IFERROR(__xludf.DUMMYFUNCTION("""COMPUTED_VALUE"""),3.67163559660212) -> 3.6716356 | D28: =IFERROR(__xludf.DUMMYFUNCTION("""COMPUTED_VALUE"""),4.74661863254814) -> 4.7466186
A29: =IFERROR(__xludf.DUMMYFUNCTION("""COMPUTED_VALUE"""),2) -> 2 | B29: =IFERROR(__xludf.DUMMYFUNCTION("""COMPUTED_VALUE"""),3.52762990087133) -> 3.5276299 | C29: =IFERROR(__xludf.DUMMYFUNCTION("""COMPUTED_VALUE"""),3.7008767083769) -> 3.7008767 | D29: =IFERROR(__xludf.DUMMYFUNCTION("""COMPUTED_VALUE"""),4.75359837765208) -> 4.7535984
A30: =IFERROR(__xludf.DUMMYFUNCTION("""COMPUTED_VALUE"""),2) -> 2 | B30: =IFERROR(__xludf.DUMMYFUNCTION("""COMPUTED_VALUE"""),3.53630587235103) -> 3.5363059 | C30: =IFERROR(__xludf.DUMMYFUNCTION("""COMPUTED_VALUE"""),3.56253076886226) -> 3.5625308 | D30: =IFERROR(__xludf.DUMMYFUNCTION("""COMPUTED_VALUE"""),4.80792720421455) -> 4.8079272
A31: =IFERROR(__xludf.DUMMYFUNCTION("""COMPUTED_VALUE"""),2) -> 2 | B31: =IFERROR(__xludf.DUMMYFUNCTION("""COMPUTED_VALUE"""),3.52283531366053) -> 3.5228353 | C31: =IFERROR(__xludf.DUMMYFUNCTION("""COMPUTED_VALUE"""),3.91871166538232) -> 3.9187117 | D31: =IFERROR(__xludf.DUMMYFUNCTION("""COMPUTED_VALUE"""),4.76107042562558) -> 4.7610704
A32: =IFERROR(__xludf.DUMMYFUNCTION("""COMPUTED_VALUE"""),2) -> 2 | B32: =IFERROR(__xludf.DUMMYFUNCTION("""COMPUTED_VALUE"""),3.47334096418593) -> 3.473341 | C32: =IFERROR(__xludf.DUMMYFUNCTION("""COMPUTED_VALUE"""),3.74241088058049) -> 3.7424109 | D32: =IFERROR(__xludf.DUMMYFUNCTION("""COMPUTED_VALUE"""),4.78135319690533) -> 4.7813532
A33: =IFERROR(__xludf.DUMMYFUNCTION("""COMPUTED_VALUE"""),2) -> 2 | B33: =IFERROR(__xludf.DUMMYFUNCTION("""COMPUTED_VALUE"""),3.55654370848351) -> 3.5565437 | C33: =IFERROR(__xludf.DUMMYFUNCTION("""COMPUTED_VALUE"""),3.6431564656197) -> 3.6431565 | D33: =IFERROR(__xludf.DUMMYFUNCTION("""COMPUTED_VALUE"""),4.63804974826438) -> 4.6380497
A34: =IFERROR(__xludf.DUMMYFUNCTION("""COMPUTED_VALUE"""),2) -> 2 | B34: =IFERROR(__xludf.DUMMYFUNCTION("""COMPUTED_VALUE"""),3.48967729166369) -> 3.4896773 | C34: =IFERROR(__xludf.DUMMYFUNCTION("""COMPUTED_VALUE"""),3.6236627073562) -> 3.6236627 | D34: =IFERROR(__xludf.DUMMYFUNCTION("""COMPUTED_VALUE"""),4.72806144811563) -> 4.7280614
A35: =IFERROR(__xludf.DUMMYFUNCTION("""COMPUTED_VALUE"""),2) -> 2 | B35: =IFERROR(__xludf.DUMMYFUNCTION("""COMPUTED_VALUE"""),3.5762261374496) -> 3.5762261 | C35: =IFERROR(__xludf.DUMMYFUNCTION("""COMPUTED_VALUE"""),3.64933485871214) -> 3.6493349 | D35: =IFERROR(__xludf.DUMMYFUNCTION("""COMPUTED_VALUE"""),4.68020856119211) -> 4.6802086
A36: =IFERROR(__xludf.DUMMYFUNCTION("""COMPUTED_VALUE"""),3) -> 3 | B36: =IFERROR(__xludf.DUMMYFUNCTION("""COMPUTED_VALUE"""),5.10659541549558) -> 5.1065954 | C36: =IFERROR(__xludf.DUMMYFUNCTION("""COMPUTED_VALUE"""),5.45716100546927) -> 5.457161 | D36: =IFERROR(__xludf.DUMMYFUNCTION("""COMPUTED_VALUE"""),6.33283762534636) -> 6.3328376
A37: =IFERROR(__xludf.DUMMYFUNCTION("""COMPUTED_VALUE"""),3) -> 3 | B37: =IFERROR(__xludf.DUMMYFUNCTION("""COMPUTED_VALUE"""),4.69156770043805) -> 4.6915677 | C37: =IFERROR(__xludf.DUMMYFUNCTION("""COMPUTED_VALUE"""),5.09129404275846) -> 5.091294 | D37: =IFERROR(__xludf.DUMMYFUNCTION("""COMPUTED_VALUE"""),6.25355606722012) -> 6.2535561
A38: =IFERROR(__xludf.DUMMYFUNCTION("""COMPUTED_VALUE"""),3) -> 3 | B38: =IFERROR(__xludf.DUMMYFUNCTION("""COMPUTED_VALUE"""),5.35052324278754) -> 5.3505232 | C38: =IFERROR(__xludf.DUMMYFUNCTION("""COMPUTED_VALUE"""),5.63684681826179) -> 5.6368468 | D38: =IFERROR(__xludf.DUMMYFUNCTION("""COMPUTED_VALUE"""),6.38375003743435) -> 6.38375
A39: =IFERROR(__xludf.DUMMYFUNCTION("""COMPUTED_VALUE"""),3) -> 3 | B39: =IFERROR(__xludf.DUMMYFUNCTION("""COMPUTED_VALUE"""),5.21221424741994) -> 5.2122142 | C39: =IFERROR(__xludf.DUMMYFUNCTION("""COMPUTED_VALUE"""),5.36410615511735) -> 5.3641062 | D39: =IFERROR(__xludf.DUMMYFUNCTION("""COMPUTED_VALUE"""),6.35465653405201) -> 6.3546565
A40: =IFERROR(__xludf.DUMMYFUNCTION("""COMPUTED_VALUE"""),3) -> 3 | B40: =IFERROR(__xludf.DUMMYFUNCTION("""COMPUTED_VALUE"""),4.93979870856182) -> 4.9397987 | C40: =IFERROR(__xludf.DUMMYFUNCTION("""COMPUTED_VALUE"""),5.09365628090447) -> 5.0936563 | D40: =IFERROR(__xludf.DUMMYFUNCTION("""COMPUTED_VALUE"""),6.22147161830738) -> 6.2214716
...

Sheet graphtotal_timevnumber critical
A1: crit pts counted | B1: Total time: All pruning | C1: Total time: old pruning | D1: Total time: no pruning | F1: For Claudia
A2: =IFERROR(__xludf.DUMMYFUNCTION("ARRAYFORMULA( FILTER( dardel_experiment_results!E2:E1000, MOD(ROW(dardel_experiment_results!E2:E1000)-ROW(dardel_experiment_results!E2), 3) = 0 ) ) "),27) -> 27 | B2: =IFERROR(__xludf.DUMMYFUNCTION("FILTER(dardel_experiment_results!K2:K1000, dardel_experiment_results!L2:L1000=""ALL (including NEW) PRUNING"")"),0.813) -> 0.813 | C2: =IFERROR(__xludf.DUMMYFUNCTION("FILTER(dardel_experiment_results!K2:K1000, dardel_experiment_results!L2:L1000=""ONLY OLD PRUNING"") "),0.891) -> 0.891 | D2: =IFERROR(__xludf.DUMMYFUNCTION("FILTER(dardel_experiment_results!K2:K1000, dardel_experiment_results!L2:L1000=""NO PRUNING WHATSOEVER"")"),3.485) -> 3.485
A3: =IFERROR(__xludf.DUMMYFUNCTION("""COMPUTED_VALUE"""),131) -> 131 | B3: =IFERROR(__xludf.DUMMYFUNCTION("""COMPUTED_VALUE"""),0.769) -> 0.769 | C3: =IFERROR(__xludf.DUMMYFUNCTION("""COMPUTED_VALUE"""),0.881) -> 0.881 | D3: =IFERROR(__xludf.DUMMYFUNCTION("""COMPUTED_VALUE"""),4.126) -> 4.126
A4: =IFERROR(__xludf.DUMMYFUNCTION("""COMPUTED_VALUE"""),379) -> 379 | B4: =IFERROR(__xludf.DUMMYFUNCTION("""COMPUTED_VALUE"""),13.377) -> 13.377 | C4: =IFERROR(__xludf.DUMMYFUNCTION("""COMPUTED_VALUE"""),34.371) -> 34.371 | D4: =IFERROR(__xludf.DUMMYFUNCTION("""COMPUTED_VALUE"""),161.453) -> 161.453
A5: =IFERROR(__xludf.DUMMYFUNCTION("""COMPUTED_VALUE"""),678) -> 678 | B5: =IFERROR(__xludf.DUMMYFUNCTION("""COMPUTED_VALUE"""),15.856) -> 15.856 | C5: =IFERROR(__xludf.DUMMYFUNCTION("""COMPUTED_VALUE"""),18.817) -> 18.817 | D5: =IFERROR(__xludf.DUMMYFUNCTION("""COMPUTED_VALUE"""),85.585) -> 85.585
A6: =IFERROR(__xludf.DUMMYFUNCTION("""COMPUTED_VALUE"""),746) -> 746 | B6: =IFERROR(__xludf.DUMMYFUNCTION("""COMPUTED_VALUE"""),17.22) -> 17.22 | C6: =IFERROR(__xludf.DUMMYFUNCTION("""COMPUTED_VALUE"""),33.146) -> 33.146 | D6: =IFERROR(__xludf.DUMMYFUNCTION("""COMPUTED_VALUE"""),188.35) -> 188.35
A7: =IFERROR(__xludf.DUMMYFUNCTION("""COMPUTED_VALUE"""),1380) -> 1380 | B7: =IFERROR(__xludf.DUMMYFUNCTION("""COMPUTED_VALUE"""),298.154) -> 298.154 | C7: =IFERROR(__xludf.DUMMYFUNCTION("""COMPUTED_VALUE"""),385.226) -> 385.226 | D7: =IFERROR(__xludf.DUMMYFUNCTION("""COMPUTED_VALUE"""),2513.296) -> 2513.296
A8: =IFERROR(__xludf.DUMMYFUNCTION("""COMPUTED_VALUE"""),27) -> 27 | B8: =IFERROR(__xludf.DUMMYFUNCTION("""COMPUTED_VALUE"""),177.882) -> 177.882 | C8: =IFERROR(__xludf.DUMMYFUNCTION("""COMPUTED_VALUE"""),466.456) -> 466.456 | D8: =IFERROR(__xludf.DUMMYFUNCTION("""COMPUTED_VALUE"""),2096.281) -> 2096.281
A9: =IFERROR(__xludf.DUMMYFUNCTION("""COMPUTED_VALUE"""),15) -> 15 | B9: =IFERROR(__xludf.DUMMYFUNCTION("""COMPUTED_VALUE"""),155.884) -> 155.884 | C9: =IFERROR(__xludf.DUMMYFUNCTION("""COMPUTED_VALUE"""),188.495) -> 188.495 | D9: =IFERROR(__xludf.DUMMYFUNCTION("""COMPUTED_VALUE"""),938.805) -> 938.805
A10: =IFERROR(__xludf.DUMMYFUNCTION("""COMPUTED_VALUE"""),21) -> 21 | B10: =IFERROR(__xludf.DUMMYFUNCTION("""COMPUTED_VALUE"""),171.154) -> 171.154 | C10: =IFERROR(__xludf.DUMMYFUNCTION("""COMPUTED_VALUE"""),324.553) -> 324.553 | D10: =IFERROR(__xludf.DUMMYFUNCTION("""COMPUTED_VALUE"""),1919.389) -> 1919.389
A11: =IFERROR(__xludf.DUMMYFUNCTION("""COMPUTED_VALUE"""),15) -> 15 | B11: =IFERROR(__xludf.DUMMYFUNCTION("""COMPUTED_VALUE"""),1486.478) -> 1486.478 | C11: =IFERROR(__xludf.DUMMYFUNCTION("""COMPUTED_VALUE"""),1918.959) -> 1918.959 | D11: =IFERROR(__xludf.DUMMYFUNCTION("""COMPUTED_VALUE"""),13081.912) -> 13081.912
A12: =IFERROR(__xludf.DUMMYFUNCTION("""COMPUTED_VALUE"""),15) -> 15 | B12: =IFERROR(__xludf.DUMMYFUNCTION("""COMPUTED_VALUE"""),763.654) -> 763.654 | C12: =IFERROR(__xludf.DUMMYFUNCTION("""COMPUTED_VALUE"""),1972.38) -> 1972.38 | D12: =IFERROR(__xludf.DUMMYFUNCTION("""COMPUTED_VALUE"""),12834.044) -> 12834.044
A13: =IFERROR(__xludf.DUMMYFUNCTION("""COMPUTED_VALUE"""),16) -> 16 | B13: =IFERROR(__xludf.DUMMYFUNCTION("""COMPUTED_VALUE"""),841.963) -> 841.963 | C13: =IFERROR(__xludf.DUMMYFUNCTION("""COMPUTED_VALUE"""),1291.901) -> 1291.901 | D13: =IFERROR(__xludf.DUMMYFUNCTION("""COMPUTED_VALUE"""),6618.973) -> 6618.973
A14: =IFERROR(__xludf.DUMMYFUNCTION("""COMPUTED_VALUE"""),130) -> 130 | B14: =IFERROR(__xludf.DUMMYFUNCTION("""COMPUTED_VALUE"""),995.241) -> 995.241 | C14: =IFERROR(__xludf.DUMMYFUNCTION("""COMPUTED_VALUE"""),2170.367) -> 2170.367 | D14: =IFERROR(__xludf.DUMMYFUNCTION("""COMPUTED_VALUE"""),12008.014) -> 12008.014
A15: =IFERROR(__xludf.DUMMYFUNCTION("""COMPUTED_VALUE"""),74) -> 74 | B15: =IFERROR(__xludf.DUMMYFUNCTION("""COMPUTED_VALUE"""),972.348) -> 972.348 | C15: =IFERROR(__xludf.DUMMYFUNCTION("""COMPUTED_VALUE"""),1541.832) -> 1541.832 | D15: =IFERROR(__xludf.DUMMYFUNCTION("""COMPUTED_VALUE"""),9765.044) -> 9765.044
A16: =IFERROR(__xludf.DUMMYFUNCTION("""COMPUTED_VALUE"""),107) -> 107 | B16: =IFERROR(__xludf.DUMMYFUNCTION("""COMPUTED_VALUE"""),200.872) -> 200.872 | C16: =IFERROR(__xludf.DUMMYFUNCTION("""COMPUTED_VALUE"""),743.819) -> 743.819 | D16: =IFERROR(__xludf.DUMMYFUNCTION("""COMPUTED_VALUE"""),5298.529) -> 5298.529
A17: =IFERROR(__xludf.DUMMYFUNCTION("""COMPUTED_VALUE"""),83) -> 83 | B17: =IFERROR(__xludf.DUMMYFUNCTION("""COMPUTED_VALUE"""),5481.828) -> 5481.828 | C17: =IFERROR(__xludf.DUMMYFUNCTION("""COMPUTED_VALUE"""),7955.522) -> 7955.522 | D17: =IFERROR(__xludf.DUMMYFUNCTION("""COMPUTED_VALUE"""),54132.065) -> 54132.065
A18: =IFERROR(__xludf.DUMMYFUNCTION("""COMPUTED_VALUE"""),84) -> 84 | B18: =IFERROR(__xludf.DUMMYFUNCTION("""COMPUTED_VALUE"""),0.382) -> 0.382 | C18: =IFERROR(__xludf.DUMMYFUNCTION("""COMPUTED_VALUE"""),0.577) -> 0.577 | D18: =IFERROR(__xludf.DUMMYFUNCTION("""COMPUTED_VALUE"""),1.495) -> 1.495
A19: =IFERROR(__xludf.DUMMYFUNCTION("""COMPUTED_VALUE"""),231) -> 231 | B19: =IFERROR(__xludf.DUMMYFUNCTION("""COMPUTED_VALUE"""),0.53) -> 0.53 | C19: =IFERROR(__xludf.DUMMYFUNCTION("""COMPUTED_VALUE"""),0.596) -> 0.596 | D19: =IFERROR(__xludf.DUMMYFUNCTION("""COMPUTED_VALUE"""),1.555) -> 1.555
A20: =IFERROR(__xludf.DUMMYFUNCTION("""COMPUTED_VALUE"""),216) -> 216 | B20: =IFERROR(__xludf.DUMMYFUNCTION("""COMPUTED_VALUE"""),0.57) -> 0.57 | C20: =IFERROR(__xludf.DUMMYFUNCTION("""COMPUTED_VALUE"""),0.735) -> 0.735 | D20: =IFERROR(__xludf.DUMMYFUNCTION("""COMPUTED_VALUE"""),2.682) -> 2.682
A21: =IFERROR(__xludf.DUMMYFUNCTION("""COMPUTED_VALUE"""),364) -> 364 | B21: =IFERROR(__xludf.DUMMYFUNCTION("""COMPUTED_VALUE"""),0.617) -> 0.617 | C21: =IFERROR(__xludf.DUMMYFUNCTION("""COMPUTED_VALUE"""),0.73) -> 0.73 | D21: =IFERROR(__xludf.DUMMYFUNCTION("""COMPUTED_VALUE"""),2.749) -> 2.749
A22: =IFERROR(__xludf.DUMMYFUNCTION("""COMPUTED_VALUE"""),219) -> 219 | B22: =IFERROR(__xludf.DUMMYFUNCTION("""COMPUTED_VALUE"""),0.538) -> 0.538 | C22: =IFERROR(__xludf.DUMMYFUNCTION("""COMPUTED_VALUE"""),0.592) -> 0.592 | D22: =IFERROR(__xludf.DUMMYFUNCTION("""COMPUTED_VALUE"""),1.52) -> 1.52
A23: =IFERROR(__xludf.DUMMYFUNCTION("""COMPUTED_VALUE"""),259) -> 259 | B23: =IFERROR(__xludf.DUMMYFUNCTION("""COMPUTED_VALUE"""),0.413) -> 0.413 | C23: =IFERROR(__xludf.DUMMYFUNCTION("""COMPUTED_VALUE"""),0.469) -> 0.469 | D23: =IFERROR(__xludf.DUMMYFUNCTION("""COMPUTED_VALUE"""),1.686) -> 1.686
A24: =IFERROR(__xludf.DUMMYFUNCTION("""COMPUTED_VALUE"""),296) -> 296 | B24: =IFERROR(__xludf.DUMMYFUNCTION("""COMPUTED_VALUE"""),0.465) -> 0.465 | C24: =IFERROR(__xludf.DUMMYFUNCTION("""COMPUTED_VALUE"""),0.555) -> 0.555 | D24: =IFERROR(__xludf.DUMMYFUNCTION("""COMPUTED_VALUE"""),1.563) -> 1.563
A25: =IFERROR(__xludf.DUMMYFUNCTION("""COMPUTED_VALUE"""),878) -> 878 | B25: =IFERROR(__xludf.DUMMYFUNCTION("""COMPUTED_VALUE"""),0.559) -> 0.559 | C25: =IFERROR(__xludf.DUMMYFUNCTION("""COMPUTED_VALUE"""),0.768) -> 0.768 | D25: =IFERROR(__xludf.DUMMYFUNCTION("""COMPUTED_VALUE"""),2.454) -> 2.454
A26: =IFERROR(__xludf.DUMMYFUNCTION("""COMPUTED_VALUE"""),643) -> 643 | B26: =IFERROR(__xludf.DUMMYFUNCTION("""COMPUTED_VALUE"""),0.498) -> 0.498 | C26: =IFERROR(__xludf.DUMMYFUNCTION("""COMPUTED_VALUE"""),0.596) -> 0.596 | D26: =IFERROR(__xludf.DUMMYFUNCTION("""COMPUTED_VALUE"""),1.642) -> 1.642
A27: =IFERROR(__xludf.DUMMYFUNCTION("""COMPUTED_VALUE"""),550) -> 550 | B27: =IFERROR(__xludf.DUMMYFUNCTION("""COMPUTED_VALUE"""),0.48) -> 0.48 | C27: =IFERROR(__xludf.DUMMYFUNCTION("""COMPUTED_VALUE"""),0.526) -> 0.526 | D27: =IFERROR(__xludf.DUMMYFUNCTION("""COMPUTED_VALUE"""),1.583) -> 1.583
A28: =IFERROR(__xludf.DUMMYFUNCTION("""COMPUTED_VALUE"""),761) -> 761 | B28: =IFERROR(__xludf.DUMMYFUNCTION("""COMPUTED_VALUE"""),0.356) -> 0.356 | C28: =IFERROR(__xludf.DUMMYFUNCTION("""COMPUTED_VALUE"""),0.53) -> 0.53 | D28: =IFERROR(__xludf.DUMMYFUNCTION("""COMPUTED_VALUE"""),1.508) -> 1.508
A29: =IFERROR(__xludf.DUMMYFUNCTION("""COMPUTED_VALUE"""),1378) -> 1378 | B29: =IFERROR(__xludf.DUMMYFUNCTION("""COMPUTED_VALUE"""),0.342) -> 0.342 | C29: =IFERROR(__xludf.DUMMYFUNCTION("""COMPUTED_VALUE"""),0.523) -> 0.523 | D29: =IFERROR(__xludf.DUMMYFUNCTION("""COMPUTED_VALUE"""),1.53) -> 1.53
A30: =IFERROR(__xludf.DUMMYFUNCTION("""COMPUTED_VALUE"""),1216) -> 1216 | B30: =IFERROR(__xludf.DUMMYFUNCTION("""COMPUTED_VALUE"""),0.423) -> 0.423 | C30: =IFERROR(__xludf.DUMMYFUNCTION("""COMPUTED_VALUE"""),0.466) -> 0.466 | D30: =IFERROR(__xludf.DUMMYFUNCTION("""COMPUTED_VALUE"""),1.476) -> 1.476
A31: =IFERROR(__xludf.DUMMYFUNCTION("""COMPUTED_VALUE"""),119) -> 119 | B31: =IFERROR(__xludf.DUMMYFUNCTION("""COMPUTED_VALUE"""),0.442) -> 0.442 | C31: =IFERROR(__xludf.DUMMYFUNCTION("""COMPUTED_VALUE"""),0.902) -> 0.902 | D31: =IFERROR(__xludf.DUMMYFUNCTION("""COMPUTED_VALUE"""),3.512) -> 3.512
A32: =IFERROR(__xludf.DUMMYFUNCTION("""COMPUTED_VALUE"""),314) -> 314 | B32: =IFERROR(__xludf.DUMMYFUNCTION("""COMPUTED_VALUE"""),0.327) -> 0.327 | C32: =IFERROR(__xludf.DUMMYFUNCTION("""COMPUTED_VALUE"""),0.513) -> 0.513 | D32: =IFERROR(__xludf.DUMMYFUNCTION("""COMPUTED_VALUE"""),1.483) -> 1.483
A33: =IFERROR(__xludf.DUMMYFUNCTION("""COMPUTED_VALUE"""),358) -> 358 | B33: =IFERROR(__xludf.DUMMYFUNCTION("""COMPUTED_VALUE"""),0.54) -> 0.54 | C33: =IFERROR(__xludf.DUMMYFUNCTION("""COMPUTED_VALUE"""),0.601) -> 0.601 | D33: =IFERROR(__xludf.DUMMYFUNCTION("""COMPUTED_VALUE"""),1.542) -> 1.542
A34: =IFERROR(__xludf.DUMMYFUNCTION("""COMPUTED_VALUE"""),678) -> 678 | B34: =IFERROR(__xludf.DUMMYFUNCTION("""COMPUTED_VALUE"""),0.407) -> 0.407 | C34: =IFERROR(__xludf.DUMMYFUNCTION("""COMPUTED_VALUE"""),0.521) -> 0.521 | D34: =IFERROR(__xludf.DUMMYFUNCTION("""COMPUTED_VALUE"""),1.704) -> 1.704
A35: =IFERROR(__xludf.DUMMYFUNCTION("""COMPUTED_VALUE"""),814) -> 814 | B35: =IFERROR(__xludf.DUMMYFUNCTION("""COMPUTED_VALUE"""),0.49) -> 0.49 | C35: =IFERROR(__xludf.DUMMYFUNCTION("""COMPUTED_VALUE"""),0.556) -> 0.556 | D35: =IFERROR(__xludf.DUMMYFUNCTION("""COMPUTED_VALUE"""),1.471) -> 1.471
A36: =IFERROR(__xludf.DUMMYFUNCTION("""COMPUTED_VALUE"""),661) -> 661 | B36: =IFERROR(__xludf.DUMMYFUNCTION("""COMPUTED_VALUE"""),5.259) -> 5.259 | C36: =IFERROR(__xludf.DUMMYFUNCTION("""COMPUTED_VALUE"""),10.401) -> 10.401 | D36: =IFERROR(__xludf.DUMMYFUNCTION("""COMPUTED_VALUE"""),52.574) -> 52.574
A37: =IFERROR(__xludf.DUMMYFUNCTION("""COMPUTED_VALUE"""),84) -> 84 | B37: =IFERROR(__xludf.DUMMYFUNCTION("""COMPUTED_VALUE"""),3.079) -> 3.079 | C37: =IFERROR(__xludf.DUMMYFUNCTION("""COMPUTED_VALUE"""),6.651) -> 6.651 | D37: =IFERROR(__xludf.DUMMYFUNCTION("""COMPUTED_VALUE"""),43.987) -> 43.987
A38: =IFERROR(__xludf.DUMMYFUNCTION("""COMPUTED_VALUE"""),102) -> 102 | B38: =IFERROR(__xludf.DUMMYFUNCTION("""COMPUTED_VALUE"""),20.994) -> 20.994 | C38: =IFERROR(__xludf.DUMMYFUNCTION("""COMPUTED_VALUE"""),39.75) -> 39.75 | D38: =IFERROR(__xludf.DUMMYFUNCTION("""COMPUTED_VALUE"""),181.833) -> 181.833
A39: =IFERROR(__xludf.DUMMYFUNCTION("""COMPUTED_VALUE"""),92) -> 92 | B39: =IFERROR(__xludf.DUMMYFUNCTION("""COMPUTED_VALUE"""),8.049) -> 8.049 | C39: =IFERROR(__xludf.DUMMYFUNCTION("""COMPUTED_VALUE"""),11.382) -> 11.382 | D39: =IFERROR(__xludf.DUMMYFUNCTION("""COMPUTED_VALUE"""),72.734) -> 72.734
A40: =IFERROR(__xludf.DUMMYFUNCTION("""COMPUTED_VALUE"""),107) -> 107 | B40: =IFERROR(__xludf.DUMMYFUNCTION("""COMPUTED_VALUE"""),4.63) -> 4.63 | C40: =IFERROR(__xludf.DUMMYFUNCTION("""COMPUTED_VALUE"""),6.208) -> 6.208 | D40: =IFERROR(__xludf.DUMMYFUNCTION("""COMPUTED_VALUE"""),36.612) -> 36.612
...

Sheet Avrg time vs sum of rectangles
